2025-06-18 12:05:18,954 - root - INFO - [app.py:203] - Starting polling thread...
2025-06-18 12:05:18,997 - werkzeug - INFO - [_internal.py:187] - [31m[1mWARNING: This is a development server. Do not use it in a production deployment. Use a production WSGI server instead.[0m
 * Running on all addresses (0.0.0.0)
 * Running on http://127.0.0.1:5000
 * Running on http://192.168.31.156:5000
2025-06-18 12:05:18,998 - werkzeug - INFO - [_internal.py:187] - [33mPress CTRL+C to quit[0m
2025-06-18 12:05:20,417 - bot.handlers - INFO - [handlers.py:116] - Chat command - User 1212235104 data: None
2025-06-18 12:05:22,646 - bot.handlers - INFO - [handlers.py:116] - Chat command - User 7988565300 data: None
2025-06-18 12:05:23,386 - bot.utils - ERROR - [utils.py:220] - Telegram API error: Forbidden: bot was blocked by the user
2025-06-18 12:05:23,388 - bot.utils - ERROR - [utils.py:243] - Unexpected error on attempt 1 for sendMessage: Forbidden: bot was blocked by the user
2025-06-18 12:05:23,389 - root - ERROR - [app.py:188] - Telegram API error for user 918355569: Unexpected error: Forbidden: bot was blocked by the user
2025-06-18 12:05:23,767 - bot.utils - ERROR - [utils.py:220] - Telegram API error: Forbidden: bot was blocked by the user
2025-06-18 12:05:23,767 - bot.utils - ERROR - [utils.py:243] - Unexpected error on attempt 1 for sendMessage: Forbidden: bot was blocked by the user
2025-06-18 12:05:23,768 - root - ERROR - [app.py:198] - Update handling error: Unexpected error: Forbidden: bot was blocked by the user
2025-06-18 12:05:23,795 - bot.handlers - INFO - [handlers.py:116] - Chat command - User 918355569 data: {'username': 'Ssssb999', 'status': 'new', 'joined_at': 1750228523.025673, 'partner': None, 'gender': None, 'interest': None, 'banned': False}
2025-06-18 12:05:23,795 - bot.handlers - INFO - [handlers.py:128] - User 918355569 profile incomplete: gender=None, interest=None
2025-06-18 12:05:24,167 - bot.utils - ERROR - [utils.py:220] - Telegram API error: Forbidden: bot was blocked by the user
2025-06-18 12:05:24,167 - bot.utils - ERROR - [utils.py:243] - Unexpected error on attempt 1 for sendMessage: Forbidden: bot was blocked by the user
2025-06-18 12:05:24,169 - root - ERROR - [app.py:188] - Telegram API error for user 918355569: Unexpected error: Forbidden: bot was blocked by the user
2025-06-18 12:05:24,554 - bot.utils - ERROR - [utils.py:220] - Telegram API error: Forbidden: bot was blocked by the user
2025-06-18 12:05:24,554 - bot.utils - ERROR - [utils.py:243] - Unexpected error on attempt 1 for sendMessage: Forbidden: bot was blocked by the user
2025-06-18 12:05:24,555 - root - ERROR - [app.py:198] - Update handling error: Unexpected error: Forbidden: bot was blocked by the user
2025-06-18 12:05:24,918 - bot.utils - ERROR - [utils.py:220] - Telegram API error: Forbidden: bot was blocked by the user
2025-06-18 12:05:24,919 - bot.utils - ERROR - [utils.py:243] - Unexpected error on attempt 1 for sendMessage: Forbidden: bot was blocked by the user
2025-06-18 12:05:24,920 - root - ERROR - [app.py:188] - Telegram API error for user 918355569: Unexpected error: Forbidden: bot was blocked by the user
2025-06-18 12:05:24,921 - bot.utils - WARNING - [utils.py:29] - Rate limit exceeded for user 918355569
2025-06-18 12:05:24,922 - bot.handlers - INFO - [handlers.py:116] - Chat command - User 918355569 data: {'username': 'Ssssb999', 'status': 'new', 'joined_at': 1750228523.025673, 'partner': None, 'gender': None, 'interest': None, 'banned': False}
2025-06-18 12:05:24,923 - bot.handlers - INFO - [handlers.py:128] - User 918355569 profile incomplete: gender=None, interest=None
2025-06-18 12:05:24,923 - bot.utils - WARNING - [utils.py:29] - Rate limit exceeded for user 918355569
2025-06-18 12:05:25,297 - bot.utils - ERROR - [utils.py:220] - Telegram API error: Forbidden: bot was blocked by the user
2025-06-18 12:05:25,298 - bot.utils - ERROR - [utils.py:243] - Unexpected error on attempt 1 for sendMessage: Forbidden: bot was blocked by the user
2025-06-18 12:05:25,299 - root - ERROR - [app.py:188] - Telegram API error for user 6654075765: Unexpected error: Forbidden: bot was blocked by the user
2025-06-18 12:05:25,673 - bot.utils - ERROR - [utils.py:220] - Telegram API error: Forbidden: bot was blocked by the user
2025-06-18 12:05:25,674 - bot.utils - ERROR - [utils.py:243] - Unexpected error on attempt 1 for sendMessage: Forbidden: bot was blocked by the user
2025-06-18 12:05:25,675 - root - ERROR - [app.py:198] - Update handling error: Unexpected error: Forbidden: bot was blocked by the user
2025-06-18 12:05:25,694 - bot.handlers - INFO - [handlers.py:116] - Chat command - User 6654075765 data: {'username': 'Major1m1', 'status': 'new', 'joined_at': 1750228524.9257162, 'partner': None, 'gender': None, 'interest': None, 'banned': False}
2025-06-18 12:05:25,694 - bot.handlers - INFO - [handlers.py:128] - User 6654075765 profile incomplete: gender=None, interest=None
2025-06-18 12:05:26,064 - bot.utils - ERROR - [utils.py:220] - Telegram API error: Forbidden: bot was blocked by the user
2025-06-18 12:05:26,065 - bot.utils - ERROR - [utils.py:243] - Unexpected error on attempt 1 for sendMessage: Forbidden: bot was blocked by the user
2025-06-18 12:05:26,066 - root - ERROR - [app.py:188] - Telegram API error for user 6654075765: Unexpected error: Forbidden: bot was blocked by the user
2025-06-18 12:05:26,442 - bot.utils - ERROR - [utils.py:220] - Telegram API error: Forbidden: bot was blocked by the user
2025-06-18 12:05:26,442 - bot.utils - ERROR - [utils.py:243] - Unexpected error on attempt 1 for sendMessage: Forbidden: bot was blocked by the user
2025-06-18 12:05:26,443 - root - ERROR - [app.py:198] - Update handling error: Unexpected error: Forbidden: bot was blocked by the user
2025-06-18 12:05:26,812 - bot.utils - ERROR - [utils.py:220] - Telegram API error: Forbidden: bot was blocked by the user
2025-06-18 12:05:26,813 - bot.utils - ERROR - [utils.py:243] - Unexpected error on attempt 1 for sendMessage: Forbidden: bot was blocked by the user
2025-06-18 12:05:26,814 - root - ERROR - [app.py:188] - Telegram API error for user 6654075765: Unexpected error: Forbidden: bot was blocked by the user
2025-06-18 12:05:26,814 - bot.utils - WARNING - [utils.py:29] - Rate limit exceeded for user 6654075765
2025-06-18 12:05:26,815 - bot.utils - WARNING - [utils.py:29] - Rate limit exceeded for user 6654075765
2025-06-18 12:05:26,817 - bot.handlers - INFO - [handlers.py:116] - Chat command - User 6654075765 data: {'username': 'Major1m1', 'status': 'new', 'joined_at': 1750228524.9257162, 'partner': None, 'gender': None, 'interest': None, 'banned': False}
2025-06-18 12:05:26,817 - bot.handlers - INFO - [handlers.py:128] - User 6654075765 profile incomplete: gender=None, interest=None
2025-06-18 12:05:26,818 - bot.utils - WARNING - [utils.py:29] - Rate limit exceeded for user 6654075765
2025-06-18 12:05:26,820 - bot.handlers - INFO - [handlers.py:116] - Chat command - User 6654075765 data: {'username': 'Major1m1', 'status': 'new', 'joined_at': 1750228524.9257162, 'partner': None, 'gender': None, 'interest': None, 'banned': False}
2025-06-18 12:05:26,820 - bot.handlers - INFO - [handlers.py:128] - User 6654075765 profile incomplete: gender=None, interest=None
2025-06-18 12:05:26,821 - bot.utils - WARNING - [utils.py:29] - Rate limit exceeded for user 6654075765
2025-06-18 12:05:26,822 - bot.utils - WARNING - [utils.py:29] - Rate limit exceeded for user 6654075765
2025-06-18 12:05:26,823 - bot.utils - WARNING - [utils.py:29] - Rate limit exceeded for user 6654075765
2025-06-18 12:05:27,190 - bot.utils - ERROR - [utils.py:220] - Telegram API error: Forbidden: bot was blocked by the user
2025-06-18 12:05:27,191 - bot.utils - ERROR - [utils.py:243] - Unexpected error on attempt 1 for sendMessage: Forbidden: bot was blocked by the user
2025-06-18 12:05:27,192 - root - ERROR - [app.py:188] - Telegram API error for user 6519443888: Unexpected error: Forbidden: bot was blocked by the user
2025-06-18 12:05:27,570 - bot.utils - ERROR - [utils.py:220] - Telegram API error: Forbidden: bot was blocked by the user
2025-06-18 12:05:27,571 - bot.utils - ERROR - [utils.py:243] - Unexpected error on attempt 1 for sendMessage: Forbidden: bot was blocked by the user
2025-06-18 12:05:27,571 - root - ERROR - [app.py:198] - Update handling error: Unexpected error: Forbidden: bot was blocked by the user
2025-06-18 12:05:27,593 - bot.handlers - INFO - [handlers.py:116] - Chat command - User 6519443888 data: {'username': 'raoabujar01', 'status': 'new', 'joined_at': 1750228526.8249218, 'partner': None, 'gender': None, 'interest': None, 'banned': False}
2025-06-18 12:05:27,594 - bot.handlers - INFO - [handlers.py:128] - User 6519443888 profile incomplete: gender=None, interest=None
2025-06-18 12:05:27,956 - bot.utils - ERROR - [utils.py:220] - Telegram API error: Forbidden: bot was blocked by the user
2025-06-18 12:05:27,957 - bot.utils - ERROR - [utils.py:243] - Unexpected error on attempt 1 for sendMessage: Forbidden: bot was blocked by the user
2025-06-18 12:05:27,958 - root - ERROR - [app.py:188] - Telegram API error for user 6519443888: Unexpected error: Forbidden: bot was blocked by the user
2025-06-18 12:05:28,325 - bot.utils - ERROR - [utils.py:220] - Telegram API error: Forbidden: bot was blocked by the user
2025-06-18 12:05:28,326 - bot.utils - ERROR - [utils.py:243] - Unexpected error on attempt 1 for sendMessage: Forbidden: bot was blocked by the user
2025-06-18 12:05:28,327 - root - ERROR - [app.py:198] - Update handling error: Unexpected error: Forbidden: bot was blocked by the user
2025-06-18 12:05:28,724 - bot.utils - ERROR - [utils.py:220] - Telegram API error: Forbidden: bot was blocked by the user
2025-06-18 12:05:28,725 - bot.utils - ERROR - [utils.py:243] - Unexpected error on attempt 1 for sendMessage: Forbidden: bot was blocked by the user
2025-06-18 12:05:28,726 - root - ERROR - [app.py:188] - Telegram API error for user 7979001635: Unexpected error: Forbidden: bot was blocked by the user
2025-06-18 12:05:29,105 - bot.utils - ERROR - [utils.py:220] - Telegram API error: Forbidden: bot was blocked by the user
2025-06-18 12:05:29,106 - bot.utils - ERROR - [utils.py:243] - Unexpected error on attempt 1 for sendMessage: Forbidden: bot was blocked by the user
2025-06-18 12:05:29,106 - root - ERROR - [app.py:198] - Update handling error: Unexpected error: Forbidden: bot was blocked by the user
2025-06-18 12:05:29,128 - bot.handlers - INFO - [handlers.py:116] - Chat command - User 7979001635 data: {'username': 'abdullahkhalid5', 'status': 'new', 'joined_at': 1750228528.332703, 'partner': None, 'gender': None, 'interest': None, 'banned': False}
2025-06-18 12:05:29,129 - bot.handlers - INFO - [handlers.py:128] - User 7979001635 profile incomplete: gender=None, interest=None
2025-06-18 12:05:29,508 - bot.utils - ERROR - [utils.py:220] - Telegram API error: Forbidden: bot was blocked by the user
2025-06-18 12:05:29,509 - bot.utils - ERROR - [utils.py:243] - Unexpected error on attempt 1 for sendMessage: Forbidden: bot was blocked by the user
2025-06-18 12:05:29,509 - root - ERROR - [app.py:188] - Telegram API error for user 7979001635: Unexpected error: Forbidden: bot was blocked by the user
2025-06-18 12:05:29,881 - bot.utils - ERROR - [utils.py:220] - Telegram API error: Forbidden: bot was blocked by the user
2025-06-18 12:05:29,882 - bot.utils - ERROR - [utils.py:243] - Unexpected error on attempt 1 for sendMessage: Forbidden: bot was blocked by the user
2025-06-18 12:05:29,883 - root - ERROR - [app.py:198] - Update handling error: Unexpected error: Forbidden: bot was blocked by the user
2025-06-18 12:16:41,247 - root - INFO - [app.py:203] - Starting polling thread...
2025-06-18 12:16:41,277 - werkzeug - INFO - [_internal.py:187] - [31m[1mWARNING: This is a development server. Do not use it in a production deployment. Use a production WSGI server instead.[0m
 * Running on all addresses (0.0.0.0)
 * Running on http://127.0.0.1:5000
 * Running on http://192.168.31.156:5000
2025-06-18 12:16:41,278 - werkzeug - INFO - [_internal.py:187] - [33mPress CTRL+C to quit[0m
2025-06-18 12:16:47,765 - root - INFO - [app.py:441] - Request started: GET /
2025-06-18 12:16:47,786 - root - INFO - [app.py:450] - Request completed: GET / - Status: 200 - Duration: 0.02s
2025-06-18 12:16:47,788 - werkzeug - INFO - [_internal.py:187] - 192.168.31.156 - - [18/Jun/2025 12:16:47] "GET / HTTP/1.1" 200 -
2025-06-18 12:16:48,878 - root - INFO - [app.py:441] - Request started: GET /favicon.ico
2025-06-18 12:16:48,879 - app - ERROR - [app.py:1414] - Exception on /favicon.ico [GET]
Traceback (most recent call last):
  File "D:\Development\unknown_chat_bot v02\telegram_bot\.venv\Lib\site-packages\flask\app.py", line 1484, in full_dispatch_request
    rv = self.dispatch_request()
         ^^^^^^^^^^^^^^^^^^^^^^^
  File "D:\Development\unknown_chat_bot v02\telegram_bot\.venv\Lib\site-packages\flask\app.py", line 1458, in dispatch_request
    self.raise_routing_exception(req)
  File "D:\Development\unknown_chat_bot v02\telegram_bot\.venv\Lib\site-packages\flask\app.py", line 1440, in raise_routing_exception
    raise request.routing_exception  # type: ignore
    ^^^^^^^^^^^^^^^^^^^^^^^^^^^^^^^
  File "D:\Development\unknown_chat_bot v02\telegram_bot\.venv\Lib\site-packages\flask\ctx.py", line 353, in match_request
    result = self.url_adapter.match(return_rule=True)  # type: ignore
             ^^^^^^^^^^^^^^^^^^^^^^^^^^^^^^^^^^^^^^^^
  File "D:\Development\unknown_chat_bot v02\telegram_bot\.venv\Lib\site-packages\werkzeug\routing\map.py", line 655, in match
    raise NotFound() from None
werkzeug.exceptions.NotFound: 404 Not Found: The requested URL was not found on the server. If you entered the URL manually please check your spelling and try again.

During handling of the above exception, another exception occurred:

Traceback (most recent call last):
  File "D:\Development\unknown_chat_bot v02\telegram_bot\.venv\Lib\site-packages\flask\app.py", line 2190, in wsgi_app
    response = self.full_dispatch_request()
               ^^^^^^^^^^^^^^^^^^^^^^^^^^^^
  File "D:\Development\unknown_chat_bot v02\telegram_bot\.venv\Lib\site-packages\flask\app.py", line 1486, in full_dispatch_request
    rv = self.handle_user_exception(e)
         ^^^^^^^^^^^^^^^^^^^^^^^^^^^^^
  File "D:\Development\unknown_chat_bot v02\telegram_bot\.venv\Lib\site-packages\flask\app.py", line 1341, in handle_user_exception
    return self.handle_http_exception(e)
           ^^^^^^^^^^^^^^^^^^^^^^^^^^^^^
  File "D:\Development\unknown_chat_bot v02\telegram_bot\.venv\Lib\site-packages\flask\app.py", line 1281, in handle_http_exception
    return self.ensure_sync(handler)(e)
           ^^^^^^^^^^^^^^^^^^^^^^^^^^^^
  File "D:\Development\unknown_chat_bot v02\telegram_bot\error_handlers.py", line 37, in not_found_error
    if request.path.startswith('/api/'):
       ^^^^^^^
NameError: name 'request' is not defined
2025-06-18 12:16:48,893 - error_handlers - ERROR - [error_handlers.py:48] - Internal Server Error: 500 Internal Server Error: The server encountered an internal error and was unable to complete your request. Either the server is overloaded or there is an error in the application.
2025-06-18 12:16:48,899 - error_handlers - ERROR - [error_handlers.py:49] - Traceback (most recent call last):
  File "D:\Development\unknown_chat_bot v02\telegram_bot\.venv\Lib\site-packages\flask\app.py", line 1484, in full_dispatch_request
    rv = self.dispatch_request()
         ^^^^^^^^^^^^^^^^^^^^^^^
  File "D:\Development\unknown_chat_bot v02\telegram_bot\.venv\Lib\site-packages\flask\app.py", line 1458, in dispatch_request
    self.raise_routing_exception(req)
  File "D:\Development\unknown_chat_bot v02\telegram_bot\.venv\Lib\site-packages\flask\app.py", line 1440, in raise_routing_exception
    raise request.routing_exception  # type: ignore
    ^^^^^^^^^^^^^^^^^^^^^^^^^^^^^^^
  File "D:\Development\unknown_chat_bot v02\telegram_bot\.venv\Lib\site-packages\flask\ctx.py", line 353, in match_request
    result = self.url_adapter.match(return_rule=True)  # type: ignore
             ^^^^^^^^^^^^^^^^^^^^^^^^^^^^^^^^^^^^^^^^
  File "D:\Development\unknown_chat_bot v02\telegram_bot\.venv\Lib\site-packages\werkzeug\routing\map.py", line 655, in match
    raise NotFound() from None
werkzeug.exceptions.NotFound: 404 Not Found: The requested URL was not found on the server. If you entered the URL manually please check your spelling and try again.

During handling of the above exception, another exception occurred:

Traceback (most recent call last):
  File "D:\Development\unknown_chat_bot v02\telegram_bot\.venv\Lib\site-packages\flask\app.py", line 2190, in wsgi_app
    response = self.full_dispatch_request()
               ^^^^^^^^^^^^^^^^^^^^^^^^^^^^
  File "D:\Development\unknown_chat_bot v02\telegram_bot\.venv\Lib\site-packages\flask\app.py", line 1486, in full_dispatch_request
    rv = self.handle_user_exception(e)
         ^^^^^^^^^^^^^^^^^^^^^^^^^^^^^
  File "D:\Development\unknown_chat_bot v02\telegram_bot\.venv\Lib\site-packages\flask\app.py", line 1341, in handle_user_exception
    return self.handle_http_exception(e)
           ^^^^^^^^^^^^^^^^^^^^^^^^^^^^^
  File "D:\Development\unknown_chat_bot v02\telegram_bot\.venv\Lib\site-packages\flask\app.py", line 1281, in handle_http_exception
    return self.ensure_sync(handler)(e)
           ^^^^^^^^^^^^^^^^^^^^^^^^^^^^
  File "D:\Development\unknown_chat_bot v02\telegram_bot\error_handlers.py", line 37, in not_found_error
    if request.path.startswith('/api/'):
       ^^^^^^^
NameError: name 'request' is not defined

2025-06-18 12:16:48,902 - werkzeug - INFO - [_internal.py:187] - 192.168.31.156 - - [18/Jun/2025 12:16:48] "[35m[1mGET /favicon.ico HTTP/1.1[0m" 500 -
2025-06-18 12:16:48,926 - werkzeug - ERROR - [_internal.py:187] - Error on request:
Traceback (most recent call last):
  File "D:\Development\unknown_chat_bot v02\telegram_bot\.venv\Lib\site-packages\flask\app.py", line 1484, in full_dispatch_request
    rv = self.dispatch_request()
         ^^^^^^^^^^^^^^^^^^^^^^^
  File "D:\Development\unknown_chat_bot v02\telegram_bot\.venv\Lib\site-packages\flask\app.py", line 1458, in dispatch_request
    self.raise_routing_exception(req)
  File "D:\Development\unknown_chat_bot v02\telegram_bot\.venv\Lib\site-packages\flask\app.py", line 1440, in raise_routing_exception
    raise request.routing_exception  # type: ignore
  File "D:\Development\unknown_chat_bot v02\telegram_bot\.venv\Lib\site-packages\flask\ctx.py", line 353, in match_request
    result = self.url_adapter.match(return_rule=True)  # type: ignore
             ^^^^^^^^^^^^^^^^^^^^^^^^^^^^^^^^^^^^^^^^^^^^^^^^^^^^^^^^
  File "D:\Development\unknown_chat_bot v02\telegram_bot\.venv\Lib\site-packages\werkzeug\routing\map.py", line 655, in match
    raise NotFound() from None
werkzeug.exceptions.NotFound: 404 Not Found: The requested URL was not found on the server. If you entered the URL manually please check your spelling and try again.

During handling of the above exception, another exception occurred:

Traceback (most recent call last):
  File "D:\Development\unknown_chat_bot v02\telegram_bot\.venv\Lib\site-packages\flask\app.py", line 2190, in wsgi_app
    response = self.full_dispatch_request()
               ^^^^^^^^^^^^^^^^^^^^^^^^^^^^
  File "D:\Development\unknown_chat_bot v02\telegram_bot\.venv\Lib\site-packages\flask\app.py", line 1486, in full_dispatch_request
    rv = self.handle_user_exception(e)
         ^^^^^^^^^^^^^^^^^^^^^^^^^^^^^
  File "D:\Development\unknown_chat_bot v02\telegram_bot\.venv\Lib\site-packages\flask\app.py", line 1341, in handle_user_exception
    return self.handle_http_exception(e)
           ^^^^^^^^^^^^^^^^^^^^^^^^^^^^^
  File "D:\Development\unknown_chat_bot v02\telegram_bot\.venv\Lib\site-packages\flask\app.py", line 1281, in handle_http_exception
    return self.ensure_sync(handler)(e)
           ^^^^^^^^^^^^^^^^^^^^^^^^^^^^
  File "D:\Development\unknown_chat_bot v02\telegram_bot\error_handlers.py", line 37, in not_found_error
    if request.path.startswith('/api/'):
       ^^^^^^^^^^^^^^^^^^^^^^^^^^^^^^^^^
NameError: name 'request' is not defined

During handling of the above exception, another exception occurred:

Traceback (most recent call last):
  File "D:\Development\unknown_chat_bot v02\telegram_bot\.venv\Lib\site-packages\werkzeug\serving.py", line 364, in run_wsgi
    execute(self.server.app)
  File "D:\Development\unknown_chat_bot v02\telegram_bot\.venv\Lib\site-packages\werkzeug\serving.py", line 325, in execute
    application_iter = app(environ, start_response)
                       ^^^^^^^^^^^^^^^^^^^^^^^^^^^^
  File "D:\Development\unknown_chat_bot v02\telegram_bot\.venv\Lib\site-packages\flask\app.py", line 2213, in __call__
    return self.wsgi_app(environ, start_response)
           ^^^^^^^^^^^^^^^^^^^^^^^^^^^^^^^^^^^^^^
  File "D:\Development\unknown_chat_bot v02\telegram_bot\.venv\Lib\site-packages\flask_socketio\__init__.py", line 43, in __call__
    return super(_SocketIOMiddleware, self).__call__(environ,
           ^^^^^^^^^^^^^^^^^^^^^^^^^^^^^^^^^^^^^^^^^^^^^^^^^^
  File "D:\Development\unknown_chat_bot v02\telegram_bot\.venv\Lib\site-packages\engineio\middleware.py", line 74, in __call__
    return self.wsgi_app(environ, start_response)
           ^^^^^^^^^^^^^^^^^^^^^^^^^^^^^^^^^^^^^^
  File "D:\Development\unknown_chat_bot v02\telegram_bot\.venv\Lib\site-packages\flask\app.py", line 2193, in wsgi_app
    response = self.handle_exception(e)
               ^^^^^^^^^^^^^^^^^^^^^^^^
  File "D:\Development\unknown_chat_bot v02\telegram_bot\.venv\Lib\site-packages\flask\app.py", line 1399, in handle_exception
    server_error = self.ensure_sync(handler)(server_error)
                   ^^^^^^^^^^^^^^^^^^^^^^^^^^^^^^^^^^^^^^^
  File "D:\Development\unknown_chat_bot v02\telegram_bot\error_handlers.py", line 50, in internal_error
    if request.path.startswith('/api/'):
       ^^^^^^^^^^^^^^^^^^^^^^^^^^^^^^^^^
NameError: name 'request' is not defined
2025-06-18 12:16:49,441 - root - INFO - [app.py:441] - Request started: GET /favicon.ico
2025-06-18 12:16:49,442 - app - ERROR - [app.py:1414] - Exception on /favicon.ico [GET]
Traceback (most recent call last):
  File "D:\Development\unknown_chat_bot v02\telegram_bot\.venv\Lib\site-packages\flask\app.py", line 1484, in full_dispatch_request
    rv = self.dispatch_request()
         ^^^^^^^^^^^^^^^^^^^^^^^
  File "D:\Development\unknown_chat_bot v02\telegram_bot\.venv\Lib\site-packages\flask\app.py", line 1458, in dispatch_request
    self.raise_routing_exception(req)
  File "D:\Development\unknown_chat_bot v02\telegram_bot\.venv\Lib\site-packages\flask\app.py", line 1440, in raise_routing_exception
    raise request.routing_exception  # type: ignore
    ^^^^^^^^^^^^^^^^^^^^^^^^^^^^^^^
  File "D:\Development\unknown_chat_bot v02\telegram_bot\.venv\Lib\site-packages\flask\ctx.py", line 353, in match_request
    result = self.url_adapter.match(return_rule=True)  # type: ignore
             ^^^^^^^^^^^^^^^^^^^^^^^^^^^^^^^^^^^^^^^^
  File "D:\Development\unknown_chat_bot v02\telegram_bot\.venv\Lib\site-packages\werkzeug\routing\map.py", line 655, in match
    raise NotFound() from None
werkzeug.exceptions.NotFound: 404 Not Found: The requested URL was not found on the server. If you entered the URL manually please check your spelling and try again.

During handling of the above exception, another exception occurred:

Traceback (most recent call last):
  File "D:\Development\unknown_chat_bot v02\telegram_bot\.venv\Lib\site-packages\flask\app.py", line 2190, in wsgi_app
    response = self.full_dispatch_request()
               ^^^^^^^^^^^^^^^^^^^^^^^^^^^^
  File "D:\Development\unknown_chat_bot v02\telegram_bot\.venv\Lib\site-packages\flask\app.py", line 1486, in full_dispatch_request
    rv = self.handle_user_exception(e)
         ^^^^^^^^^^^^^^^^^^^^^^^^^^^^^
  File "D:\Development\unknown_chat_bot v02\telegram_bot\.venv\Lib\site-packages\flask\app.py", line 1341, in handle_user_exception
    return self.handle_http_exception(e)
           ^^^^^^^^^^^^^^^^^^^^^^^^^^^^^
  File "D:\Development\unknown_chat_bot v02\telegram_bot\.venv\Lib\site-packages\flask\app.py", line 1281, in handle_http_exception
    return self.ensure_sync(handler)(e)
           ^^^^^^^^^^^^^^^^^^^^^^^^^^^^
  File "D:\Development\unknown_chat_bot v02\telegram_bot\error_handlers.py", line 37, in not_found_error
    if request.path.startswith('/api/'):
       ^^^^^^^
NameError: name 'request' is not defined
2025-06-18 12:16:49,449 - error_handlers - ERROR - [error_handlers.py:48] - Internal Server Error: 500 Internal Server Error: The server encountered an internal error and was unable to complete your request. Either the server is overloaded or there is an error in the application.
2025-06-18 12:16:49,454 - error_handlers - ERROR - [error_handlers.py:49] - Traceback (most recent call last):
  File "D:\Development\unknown_chat_bot v02\telegram_bot\.venv\Lib\site-packages\flask\app.py", line 1484, in full_dispatch_request
    rv = self.dispatch_request()
         ^^^^^^^^^^^^^^^^^^^^^^^
  File "D:\Development\unknown_chat_bot v02\telegram_bot\.venv\Lib\site-packages\flask\app.py", line 1458, in dispatch_request
    self.raise_routing_exception(req)
  File "D:\Development\unknown_chat_bot v02\telegram_bot\.venv\Lib\site-packages\flask\app.py", line 1440, in raise_routing_exception
    raise request.routing_exception  # type: ignore
    ^^^^^^^^^^^^^^^^^^^^^^^^^^^^^^^
  File "D:\Development\unknown_chat_bot v02\telegram_bot\.venv\Lib\site-packages\flask\ctx.py", line 353, in match_request
    result = self.url_adapter.match(return_rule=True)  # type: ignore
             ^^^^^^^^^^^^^^^^^^^^^^^^^^^^^^^^^^^^^^^^
  File "D:\Development\unknown_chat_bot v02\telegram_bot\.venv\Lib\site-packages\werkzeug\routing\map.py", line 655, in match
    raise NotFound() from None
werkzeug.exceptions.NotFound: 404 Not Found: The requested URL was not found on the server. If you entered the URL manually please check your spelling and try again.

During handling of the above exception, another exception occurred:

Traceback (most recent call last):
  File "D:\Development\unknown_chat_bot v02\telegram_bot\.venv\Lib\site-packages\flask\app.py", line 2190, in wsgi_app
    response = self.full_dispatch_request()
               ^^^^^^^^^^^^^^^^^^^^^^^^^^^^
  File "D:\Development\unknown_chat_bot v02\telegram_bot\.venv\Lib\site-packages\flask\app.py", line 1486, in full_dispatch_request
    rv = self.handle_user_exception(e)
         ^^^^^^^^^^^^^^^^^^^^^^^^^^^^^
  File "D:\Development\unknown_chat_bot v02\telegram_bot\.venv\Lib\site-packages\flask\app.py", line 1341, in handle_user_exception
    return self.handle_http_exception(e)
           ^^^^^^^^^^^^^^^^^^^^^^^^^^^^^
  File "D:\Development\unknown_chat_bot v02\telegram_bot\.venv\Lib\site-packages\flask\app.py", line 1281, in handle_http_exception
    return self.ensure_sync(handler)(e)
           ^^^^^^^^^^^^^^^^^^^^^^^^^^^^
  File "D:\Development\unknown_chat_bot v02\telegram_bot\error_handlers.py", line 37, in not_found_error
    if request.path.startswith('/api/'):
       ^^^^^^^
NameError: name 'request' is not defined

2025-06-18 12:16:49,457 - werkzeug - INFO - [_internal.py:187] - 192.168.31.156 - - [18/Jun/2025 12:16:49] "[35m[1mGET /favicon.ico HTTP/1.1[0m" 500 -
2025-06-18 12:16:49,472 - werkzeug - ERROR - [_internal.py:187] - Error on request:
Traceback (most recent call last):
  File "D:\Development\unknown_chat_bot v02\telegram_bot\.venv\Lib\site-packages\flask\app.py", line 1484, in full_dispatch_request
    rv = self.dispatch_request()
         ^^^^^^^^^^^^^^^^^^^^^^^
  File "D:\Development\unknown_chat_bot v02\telegram_bot\.venv\Lib\site-packages\flask\app.py", line 1458, in dispatch_request
    self.raise_routing_exception(req)
  File "D:\Development\unknown_chat_bot v02\telegram_bot\.venv\Lib\site-packages\flask\app.py", line 1440, in raise_routing_exception
    raise request.routing_exception  # type: ignore
  File "D:\Development\unknown_chat_bot v02\telegram_bot\.venv\Lib\site-packages\flask\ctx.py", line 353, in match_request
    result = self.url_adapter.match(return_rule=True)  # type: ignore
             ^^^^^^^^^^^^^^^^^^^^^^^^^^^^^^^^^^^^^^^^^^^^^^^^^^^^^^^^
  File "D:\Development\unknown_chat_bot v02\telegram_bot\.venv\Lib\site-packages\werkzeug\routing\map.py", line 655, in match
    raise NotFound() from None
werkzeug.exceptions.NotFound: 404 Not Found: The requested URL was not found on the server. If you entered the URL manually please check your spelling and try again.

During handling of the above exception, another exception occurred:

Traceback (most recent call last):
  File "D:\Development\unknown_chat_bot v02\telegram_bot\.venv\Lib\site-packages\flask\app.py", line 2190, in wsgi_app
    response = self.full_dispatch_request()
               ^^^^^^^^^^^^^^^^^^^^^^^^^^^^
  File "D:\Development\unknown_chat_bot v02\telegram_bot\.venv\Lib\site-packages\flask\app.py", line 1486, in full_dispatch_request
    rv = self.handle_user_exception(e)
         ^^^^^^^^^^^^^^^^^^^^^^^^^^^^^
  File "D:\Development\unknown_chat_bot v02\telegram_bot\.venv\Lib\site-packages\flask\app.py", line 1341, in handle_user_exception
    return self.handle_http_exception(e)
           ^^^^^^^^^^^^^^^^^^^^^^^^^^^^^
  File "D:\Development\unknown_chat_bot v02\telegram_bot\.venv\Lib\site-packages\flask\app.py", line 1281, in handle_http_exception
    return self.ensure_sync(handler)(e)
           ^^^^^^^^^^^^^^^^^^^^^^^^^^^^
  File "D:\Development\unknown_chat_bot v02\telegram_bot\error_handlers.py", line 37, in not_found_error
    if request.path.startswith('/api/'):
       ^^^^^^^^^^^^^^^^^^^^^^^^^^^^^^^^^
NameError: name 'request' is not defined

During handling of the above exception, another exception occurred:

Traceback (most recent call last):
  File "D:\Development\unknown_chat_bot v02\telegram_bot\.venv\Lib\site-packages\werkzeug\serving.py", line 364, in run_wsgi
    execute(self.server.app)
  File "D:\Development\unknown_chat_bot v02\telegram_bot\.venv\Lib\site-packages\werkzeug\serving.py", line 325, in execute
    application_iter = app(environ, start_response)
                       ^^^^^^^^^^^^^^^^^^^^^^^^^^^^
  File "D:\Development\unknown_chat_bot v02\telegram_bot\.venv\Lib\site-packages\flask\app.py", line 2213, in __call__
    return self.wsgi_app(environ, start_response)
           ^^^^^^^^^^^^^^^^^^^^^^^^^^^^^^^^^^^^^^
  File "D:\Development\unknown_chat_bot v02\telegram_bot\.venv\Lib\site-packages\flask_socketio\__init__.py", line 43, in __call__
    return super(_SocketIOMiddleware, self).__call__(environ,
           ^^^^^^^^^^^^^^^^^^^^^^^^^^^^^^^^^^^^^^^^^^^^^^^^^^
  File "D:\Development\unknown_chat_bot v02\telegram_bot\.venv\Lib\site-packages\engineio\middleware.py", line 74, in __call__
    return self.wsgi_app(environ, start_response)
           ^^^^^^^^^^^^^^^^^^^^^^^^^^^^^^^^^^^^^^
  File "D:\Development\unknown_chat_bot v02\telegram_bot\.venv\Lib\site-packages\flask\app.py", line 2193, in wsgi_app
    response = self.handle_exception(e)
               ^^^^^^^^^^^^^^^^^^^^^^^^
  File "D:\Development\unknown_chat_bot v02\telegram_bot\.venv\Lib\site-packages\flask\app.py", line 1399, in handle_exception
    server_error = self.ensure_sync(handler)(server_error)
                   ^^^^^^^^^^^^^^^^^^^^^^^^^^^^^^^^^^^^^^^
  File "D:\Development\unknown_chat_bot v02\telegram_bot\error_handlers.py", line 50, in internal_error
    if request.path.startswith('/api/'):
       ^^^^^^^^^^^^^^^^^^^^^^^^^^^^^^^^^
NameError: name 'request' is not defined
2025-06-18 12:17:00,530 - root - INFO - [app.py:441] - Request started: GET /login
2025-06-18 12:17:00,578 - root - INFO - [app.py:450] - Request completed: GET /login - Status: 200 - Duration: 0.05s
2025-06-18 12:17:00,579 - werkzeug - INFO - [_internal.py:187] - 192.168.31.156 - - [18/Jun/2025 12:17:00] "GET /login HTTP/1.1" 200 -
2025-06-18 12:17:01,085 - root - INFO - [app.py:441] - Request started: GET /favicon.ico
2025-06-18 12:17:01,086 - app - ERROR - [app.py:1414] - Exception on /favicon.ico [GET]
Traceback (most recent call last):
  File "D:\Development\unknown_chat_bot v02\telegram_bot\.venv\Lib\site-packages\flask\app.py", line 1484, in full_dispatch_request
    rv = self.dispatch_request()
         ^^^^^^^^^^^^^^^^^^^^^^^
  File "D:\Development\unknown_chat_bot v02\telegram_bot\.venv\Lib\site-packages\flask\app.py", line 1458, in dispatch_request
    self.raise_routing_exception(req)
  File "D:\Development\unknown_chat_bot v02\telegram_bot\.venv\Lib\site-packages\flask\app.py", line 1440, in raise_routing_exception
    raise request.routing_exception  # type: ignore
    ^^^^^^^^^^^^^^^^^^^^^^^^^^^^^^^
  File "D:\Development\unknown_chat_bot v02\telegram_bot\.venv\Lib\site-packages\flask\ctx.py", line 353, in match_request
    result = self.url_adapter.match(return_rule=True)  # type: ignore
             ^^^^^^^^^^^^^^^^^^^^^^^^^^^^^^^^^^^^^^^^
  File "D:\Development\unknown_chat_bot v02\telegram_bot\.venv\Lib\site-packages\werkzeug\routing\map.py", line 655, in match
    raise NotFound() from None
werkzeug.exceptions.NotFound: 404 Not Found: The requested URL was not found on the server. If you entered the URL manually please check your spelling and try again.

During handling of the above exception, another exception occurred:

Traceback (most recent call last):
  File "D:\Development\unknown_chat_bot v02\telegram_bot\.venv\Lib\site-packages\flask\app.py", line 2190, in wsgi_app
    response = self.full_dispatch_request()
               ^^^^^^^^^^^^^^^^^^^^^^^^^^^^
  File "D:\Development\unknown_chat_bot v02\telegram_bot\.venv\Lib\site-packages\flask\app.py", line 1486, in full_dispatch_request
    rv = self.handle_user_exception(e)
         ^^^^^^^^^^^^^^^^^^^^^^^^^^^^^
  File "D:\Development\unknown_chat_bot v02\telegram_bot\.venv\Lib\site-packages\flask\app.py", line 1341, in handle_user_exception
    return self.handle_http_exception(e)
           ^^^^^^^^^^^^^^^^^^^^^^^^^^^^^
  File "D:\Development\unknown_chat_bot v02\telegram_bot\.venv\Lib\site-packages\flask\app.py", line 1281, in handle_http_exception
    return self.ensure_sync(handler)(e)
           ^^^^^^^^^^^^^^^^^^^^^^^^^^^^
  File "D:\Development\unknown_chat_bot v02\telegram_bot\error_handlers.py", line 37, in not_found_error
    if request.path.startswith('/api/'):
       ^^^^^^^
NameError: name 'request' is not defined
2025-06-18 12:17:01,092 - error_handlers - ERROR - [error_handlers.py:48] - Internal Server Error: 500 Internal Server Error: The server encountered an internal error and was unable to complete your request. Either the server is overloaded or there is an error in the application.
2025-06-18 12:17:01,097 - error_handlers - ERROR - [error_handlers.py:49] - Traceback (most recent call last):
  File "D:\Development\unknown_chat_bot v02\telegram_bot\.venv\Lib\site-packages\flask\app.py", line 1484, in full_dispatch_request
    rv = self.dispatch_request()
         ^^^^^^^^^^^^^^^^^^^^^^^
  File "D:\Development\unknown_chat_bot v02\telegram_bot\.venv\Lib\site-packages\flask\app.py", line 1458, in dispatch_request
    self.raise_routing_exception(req)
  File "D:\Development\unknown_chat_bot v02\telegram_bot\.venv\Lib\site-packages\flask\app.py", line 1440, in raise_routing_exception
    raise request.routing_exception  # type: ignore
    ^^^^^^^^^^^^^^^^^^^^^^^^^^^^^^^
  File "D:\Development\unknown_chat_bot v02\telegram_bot\.venv\Lib\site-packages\flask\ctx.py", line 353, in match_request
    result = self.url_adapter.match(return_rule=True)  # type: ignore
             ^^^^^^^^^^^^^^^^^^^^^^^^^^^^^^^^^^^^^^^^
  File "D:\Development\unknown_chat_bot v02\telegram_bot\.venv\Lib\site-packages\werkzeug\routing\map.py", line 655, in match
    raise NotFound() from None
werkzeug.exceptions.NotFound: 404 Not Found: The requested URL was not found on the server. If you entered the URL manually please check your spelling and try again.

During handling of the above exception, another exception occurred:

Traceback (most recent call last):
  File "D:\Development\unknown_chat_bot v02\telegram_bot\.venv\Lib\site-packages\flask\app.py", line 2190, in wsgi_app
    response = self.full_dispatch_request()
               ^^^^^^^^^^^^^^^^^^^^^^^^^^^^
  File "D:\Development\unknown_chat_bot v02\telegram_bot\.venv\Lib\site-packages\flask\app.py", line 1486, in full_dispatch_request
    rv = self.handle_user_exception(e)
         ^^^^^^^^^^^^^^^^^^^^^^^^^^^^^
  File "D:\Development\unknown_chat_bot v02\telegram_bot\.venv\Lib\site-packages\flask\app.py", line 1341, in handle_user_exception
    return self.handle_http_exception(e)
           ^^^^^^^^^^^^^^^^^^^^^^^^^^^^^
  File "D:\Development\unknown_chat_bot v02\telegram_bot\.venv\Lib\site-packages\flask\app.py", line 1281, in handle_http_exception
    return self.ensure_sync(handler)(e)
           ^^^^^^^^^^^^^^^^^^^^^^^^^^^^
  File "D:\Development\unknown_chat_bot v02\telegram_bot\error_handlers.py", line 37, in not_found_error
    if request.path.startswith('/api/'):
       ^^^^^^^
NameError: name 'request' is not defined

2025-06-18 12:17:01,099 - werkzeug - INFO - [_internal.py:187] - 192.168.31.156 - - [18/Jun/2025 12:17:01] "[35m[1mGET /favicon.ico HTTP/1.1[0m" 500 -
2025-06-18 12:17:01,121 - werkzeug - ERROR - [_internal.py:187] - Error on request:
Traceback (most recent call last):
  File "D:\Development\unknown_chat_bot v02\telegram_bot\.venv\Lib\site-packages\flask\app.py", line 1484, in full_dispatch_request
    rv = self.dispatch_request()
         ^^^^^^^^^^^^^^^^^^^^^^^
  File "D:\Development\unknown_chat_bot v02\telegram_bot\.venv\Lib\site-packages\flask\app.py", line 1458, in dispatch_request
    self.raise_routing_exception(req)
  File "D:\Development\unknown_chat_bot v02\telegram_bot\.venv\Lib\site-packages\flask\app.py", line 1440, in raise_routing_exception
    raise request.routing_exception  # type: ignore
  File "D:\Development\unknown_chat_bot v02\telegram_bot\.venv\Lib\site-packages\flask\ctx.py", line 353, in match_request
    result = self.url_adapter.match(return_rule=True)  # type: ignore
             ^^^^^^^^^^^^^^^^^^^^^^^^^^^^^^^^^^^^^^^^^^^^^^^^^^^^^^^^
  File "D:\Development\unknown_chat_bot v02\telegram_bot\.venv\Lib\site-packages\werkzeug\routing\map.py", line 655, in match
    raise NotFound() from None
werkzeug.exceptions.NotFound: 404 Not Found: The requested URL was not found on the server. If you entered the URL manually please check your spelling and try again.

During handling of the above exception, another exception occurred:

Traceback (most recent call last):
  File "D:\Development\unknown_chat_bot v02\telegram_bot\.venv\Lib\site-packages\flask\app.py", line 2190, in wsgi_app
    response = self.full_dispatch_request()
               ^^^^^^^^^^^^^^^^^^^^^^^^^^^^
  File "D:\Development\unknown_chat_bot v02\telegram_bot\.venv\Lib\site-packages\flask\app.py", line 1486, in full_dispatch_request
    rv = self.handle_user_exception(e)
         ^^^^^^^^^^^^^^^^^^^^^^^^^^^^^
  File "D:\Development\unknown_chat_bot v02\telegram_bot\.venv\Lib\site-packages\flask\app.py", line 1341, in handle_user_exception
    return self.handle_http_exception(e)
           ^^^^^^^^^^^^^^^^^^^^^^^^^^^^^
  File "D:\Development\unknown_chat_bot v02\telegram_bot\.venv\Lib\site-packages\flask\app.py", line 1281, in handle_http_exception
    return self.ensure_sync(handler)(e)
           ^^^^^^^^^^^^^^^^^^^^^^^^^^^^
  File "D:\Development\unknown_chat_bot v02\telegram_bot\error_handlers.py", line 37, in not_found_error
    if request.path.startswith('/api/'):
       ^^^^^^^^^^^^^^^^^^^^^^^^^^^^^^^^^
NameError: name 'request' is not defined

During handling of the above exception, another exception occurred:

Traceback (most recent call last):
  File "D:\Development\unknown_chat_bot v02\telegram_bot\.venv\Lib\site-packages\werkzeug\serving.py", line 364, in run_wsgi
    execute(self.server.app)
  File "D:\Development\unknown_chat_bot v02\telegram_bot\.venv\Lib\site-packages\werkzeug\serving.py", line 325, in execute
    application_iter = app(environ, start_response)
                       ^^^^^^^^^^^^^^^^^^^^^^^^^^^^
  File "D:\Development\unknown_chat_bot v02\telegram_bot\.venv\Lib\site-packages\flask\app.py", line 2213, in __call__
    return self.wsgi_app(environ, start_response)
           ^^^^^^^^^^^^^^^^^^^^^^^^^^^^^^^^^^^^^^
  File "D:\Development\unknown_chat_bot v02\telegram_bot\.venv\Lib\site-packages\flask_socketio\__init__.py", line 43, in __call__
    return super(_SocketIOMiddleware, self).__call__(environ,
           ^^^^^^^^^^^^^^^^^^^^^^^^^^^^^^^^^^^^^^^^^^^^^^^^^^
  File "D:\Development\unknown_chat_bot v02\telegram_bot\.venv\Lib\site-packages\engineio\middleware.py", line 74, in __call__
    return self.wsgi_app(environ, start_response)
           ^^^^^^^^^^^^^^^^^^^^^^^^^^^^^^^^^^^^^^
  File "D:\Development\unknown_chat_bot v02\telegram_bot\.venv\Lib\site-packages\flask\app.py", line 2193, in wsgi_app
    response = self.handle_exception(e)
               ^^^^^^^^^^^^^^^^^^^^^^^^
  File "D:\Development\unknown_chat_bot v02\telegram_bot\.venv\Lib\site-packages\flask\app.py", line 1399, in handle_exception
    server_error = self.ensure_sync(handler)(server_error)
                   ^^^^^^^^^^^^^^^^^^^^^^^^^^^^^^^^^^^^^^^
  File "D:\Development\unknown_chat_bot v02\telegram_bot\error_handlers.py", line 50, in internal_error
    if request.path.startswith('/api/'):
       ^^^^^^^^^^^^^^^^^^^^^^^^^^^^^^^^^
NameError: name 'request' is not defined
2025-06-18 12:17:13,188 - root - INFO - [app.py:441] - Request started: POST /login
2025-06-18 12:17:13,191 - root - INFO - [app.py:450] - Request completed: POST /login - Status: 302 - Duration: 0.00s
2025-06-18 12:17:13,194 - werkzeug - INFO - [_internal.py:187] - 192.168.31.156 - - [18/Jun/2025 12:17:13] "[32mPOST /login HTTP/1.1[0m" 302 -
2025-06-18 12:17:13,225 - root - INFO - [app.py:441] - Request started: GET /admin/dashboard
2025-06-18 12:17:13,251 - root - INFO - [app.py:450] - Request completed: GET /admin/dashboard - Status: 200 - Duration: 0.03s
2025-06-18 12:17:13,253 - werkzeug - INFO - [_internal.py:187] - 192.168.31.156 - - [18/Jun/2025 12:17:13] "GET /admin/dashboard HTTP/1.1" 200 -
2025-06-18 12:17:13,793 - werkzeug - INFO - [_internal.py:187] - 192.168.31.156 - - [18/Jun/2025 12:17:13] "GET /socket.io/?EIO=4&transport=polling&t=PU1oh1s HTTP/1.1" 200 -
2025-06-18 12:17:13,904 - werkzeug - INFO - [_internal.py:187] - 192.168.31.156 - - [18/Jun/2025 12:17:13] "POST /socket.io/?EIO=4&transport=polling&t=PU1oh3a&sid=RzAZw7jLRrCIRbZWAAAA HTTP/1.1" 200 -
2025-06-18 12:17:13,907 - werkzeug - INFO - [_internal.py:187] - 192.168.31.156 - - [18/Jun/2025 12:17:13] "GET /socket.io/?EIO=4&transport=polling&t=PU1oh3e&sid=RzAZw7jLRrCIRbZWAAAA HTTP/1.1" 200 -
2025-06-18 12:17:14,094 - werkzeug - INFO - [_internal.py:187] - 192.168.31.156 - - [18/Jun/2025 12:17:14] "GET /socket.io/?EIO=4&transport=polling&t=PU1oh4U&sid=RzAZw7jLRrCIRbZWAAAA HTTP/1.1" 200 -
2025-06-18 12:17:14,144 - root - INFO - [app.py:441] - Request started: GET /favicon.ico
2025-06-18 12:17:14,145 - app - ERROR - [app.py:1414] - Exception on /favicon.ico [GET]
Traceback (most recent call last):
  File "D:\Development\unknown_chat_bot v02\telegram_bot\.venv\Lib\site-packages\flask\app.py", line 1484, in full_dispatch_request
    rv = self.dispatch_request()
         ^^^^^^^^^^^^^^^^^^^^^^^
  File "D:\Development\unknown_chat_bot v02\telegram_bot\.venv\Lib\site-packages\flask\app.py", line 1458, in dispatch_request
    self.raise_routing_exception(req)
  File "D:\Development\unknown_chat_bot v02\telegram_bot\.venv\Lib\site-packages\flask\app.py", line 1440, in raise_routing_exception
    raise request.routing_exception  # type: ignore
    ^^^^^^^^^^^^^^^^^^^^^^^^^^^^^^^
  File "D:\Development\unknown_chat_bot v02\telegram_bot\.venv\Lib\site-packages\flask\ctx.py", line 353, in match_request
    result = self.url_adapter.match(return_rule=True)  # type: ignore
             ^^^^^^^^^^^^^^^^^^^^^^^^^^^^^^^^^^^^^^^^
  File "D:\Development\unknown_chat_bot v02\telegram_bot\.venv\Lib\site-packages\werkzeug\routing\map.py", line 655, in match
    raise NotFound() from None
werkzeug.exceptions.NotFound: 404 Not Found: The requested URL was not found on the server. If you entered the URL manually please check your spelling and try again.

During handling of the above exception, another exception occurred:

Traceback (most recent call last):
  File "D:\Development\unknown_chat_bot v02\telegram_bot\.venv\Lib\site-packages\flask\app.py", line 2190, in wsgi_app
    response = self.full_dispatch_request()
               ^^^^^^^^^^^^^^^^^^^^^^^^^^^^
  File "D:\Development\unknown_chat_bot v02\telegram_bot\.venv\Lib\site-packages\flask\app.py", line 1486, in full_dispatch_request
    rv = self.handle_user_exception(e)
         ^^^^^^^^^^^^^^^^^^^^^^^^^^^^^
  File "D:\Development\unknown_chat_bot v02\telegram_bot\.venv\Lib\site-packages\flask\app.py", line 1341, in handle_user_exception
    return self.handle_http_exception(e)
           ^^^^^^^^^^^^^^^^^^^^^^^^^^^^^
  File "D:\Development\unknown_chat_bot v02\telegram_bot\.venv\Lib\site-packages\flask\app.py", line 1281, in handle_http_exception
    return self.ensure_sync(handler)(e)
           ^^^^^^^^^^^^^^^^^^^^^^^^^^^^
  File "D:\Development\unknown_chat_bot v02\telegram_bot\error_handlers.py", line 37, in not_found_error
    if request.path.startswith('/api/'):
       ^^^^^^^
NameError: name 'request' is not defined
2025-06-18 12:17:14,152 - error_handlers - ERROR - [error_handlers.py:48] - Internal Server Error: 500 Internal Server Error: The server encountered an internal error and was unable to complete your request. Either the server is overloaded or there is an error in the application.
2025-06-18 12:17:14,158 - error_handlers - ERROR - [error_handlers.py:49] - Traceback (most recent call last):
  File "D:\Development\unknown_chat_bot v02\telegram_bot\.venv\Lib\site-packages\flask\app.py", line 1484, in full_dispatch_request
    rv = self.dispatch_request()
         ^^^^^^^^^^^^^^^^^^^^^^^
  File "D:\Development\unknown_chat_bot v02\telegram_bot\.venv\Lib\site-packages\flask\app.py", line 1458, in dispatch_request
    self.raise_routing_exception(req)
  File "D:\Development\unknown_chat_bot v02\telegram_bot\.venv\Lib\site-packages\flask\app.py", line 1440, in raise_routing_exception
    raise request.routing_exception  # type: ignore
    ^^^^^^^^^^^^^^^^^^^^^^^^^^^^^^^
  File "D:\Development\unknown_chat_bot v02\telegram_bot\.venv\Lib\site-packages\flask\ctx.py", line 353, in match_request
    result = self.url_adapter.match(return_rule=True)  # type: ignore
             ^^^^^^^^^^^^^^^^^^^^^^^^^^^^^^^^^^^^^^^^
  File "D:\Development\unknown_chat_bot v02\telegram_bot\.venv\Lib\site-packages\werkzeug\routing\map.py", line 655, in match
    raise NotFound() from None
werkzeug.exceptions.NotFound: 404 Not Found: The requested URL was not found on the server. If you entered the URL manually please check your spelling and try again.

During handling of the above exception, another exception occurred:

Traceback (most recent call last):
  File "D:\Development\unknown_chat_bot v02\telegram_bot\.venv\Lib\site-packages\flask\app.py", line 2190, in wsgi_app
    response = self.full_dispatch_request()
               ^^^^^^^^^^^^^^^^^^^^^^^^^^^^
  File "D:\Development\unknown_chat_bot v02\telegram_bot\.venv\Lib\site-packages\flask\app.py", line 1486, in full_dispatch_request
    rv = self.handle_user_exception(e)
         ^^^^^^^^^^^^^^^^^^^^^^^^^^^^^
  File "D:\Development\unknown_chat_bot v02\telegram_bot\.venv\Lib\site-packages\flask\app.py", line 1341, in handle_user_exception
    return self.handle_http_exception(e)
           ^^^^^^^^^^^^^^^^^^^^^^^^^^^^^
  File "D:\Development\unknown_chat_bot v02\telegram_bot\.venv\Lib\site-packages\flask\app.py", line 1281, in handle_http_exception
    return self.ensure_sync(handler)(e)
           ^^^^^^^^^^^^^^^^^^^^^^^^^^^^
  File "D:\Development\unknown_chat_bot v02\telegram_bot\error_handlers.py", line 37, in not_found_error
    if request.path.startswith('/api/'):
       ^^^^^^^
NameError: name 'request' is not defined

2025-06-18 12:17:14,160 - werkzeug - INFO - [_internal.py:187] - 192.168.31.156 - - [18/Jun/2025 12:17:14] "[35m[1mGET /favicon.ico HTTP/1.1[0m" 500 -
2025-06-18 12:17:14,187 - werkzeug - ERROR - [_internal.py:187] - Error on request:
Traceback (most recent call last):
  File "D:\Development\unknown_chat_bot v02\telegram_bot\.venv\Lib\site-packages\flask\app.py", line 1484, in full_dispatch_request
    rv = self.dispatch_request()
         ^^^^^^^^^^^^^^^^^^^^^^^
  File "D:\Development\unknown_chat_bot v02\telegram_bot\.venv\Lib\site-packages\flask\app.py", line 1458, in dispatch_request
    self.raise_routing_exception(req)
  File "D:\Development\unknown_chat_bot v02\telegram_bot\.venv\Lib\site-packages\flask\app.py", line 1440, in raise_routing_exception
    raise request.routing_exception  # type: ignore
  File "D:\Development\unknown_chat_bot v02\telegram_bot\.venv\Lib\site-packages\flask\ctx.py", line 353, in match_request
    result = self.url_adapter.match(return_rule=True)  # type: ignore
             ^^^^^^^^^^^^^^^^^^^^^^^^^^^^^^^^^^^^^^^^^^^^^^^^^^^^^^^^
  File "D:\Development\unknown_chat_bot v02\telegram_bot\.venv\Lib\site-packages\werkzeug\routing\map.py", line 655, in match
    raise NotFound() from None
werkzeug.exceptions.NotFound: 404 Not Found: The requested URL was not found on the server. If you entered the URL manually please check your spelling and try again.

During handling of the above exception, another exception occurred:

Traceback (most recent call last):
  File "D:\Development\unknown_chat_bot v02\telegram_bot\.venv\Lib\site-packages\flask\app.py", line 2190, in wsgi_app
    response = self.full_dispatch_request()
               ^^^^^^^^^^^^^^^^^^^^^^^^^^^^
  File "D:\Development\unknown_chat_bot v02\telegram_bot\.venv\Lib\site-packages\flask\app.py", line 1486, in full_dispatch_request
    rv = self.handle_user_exception(e)
         ^^^^^^^^^^^^^^^^^^^^^^^^^^^^^
  File "D:\Development\unknown_chat_bot v02\telegram_bot\.venv\Lib\site-packages\flask\app.py", line 1341, in handle_user_exception
    return self.handle_http_exception(e)
           ^^^^^^^^^^^^^^^^^^^^^^^^^^^^^
  File "D:\Development\unknown_chat_bot v02\telegram_bot\.venv\Lib\site-packages\flask\app.py", line 1281, in handle_http_exception
    return self.ensure_sync(handler)(e)
           ^^^^^^^^^^^^^^^^^^^^^^^^^^^^
  File "D:\Development\unknown_chat_bot v02\telegram_bot\error_handlers.py", line 37, in not_found_error
    if request.path.startswith('/api/'):
       ^^^^^^^^^^^^^^^^^^^^^^^^^^^^^^^^^
NameError: name 'request' is not defined

During handling of the above exception, another exception occurred:

Traceback (most recent call last):
  File "D:\Development\unknown_chat_bot v02\telegram_bot\.venv\Lib\site-packages\werkzeug\serving.py", line 364, in run_wsgi
    execute(self.server.app)
  File "D:\Development\unknown_chat_bot v02\telegram_bot\.venv\Lib\site-packages\werkzeug\serving.py", line 325, in execute
    application_iter = app(environ, start_response)
                       ^^^^^^^^^^^^^^^^^^^^^^^^^^^^
  File "D:\Development\unknown_chat_bot v02\telegram_bot\.venv\Lib\site-packages\flask\app.py", line 2213, in __call__
    return self.wsgi_app(environ, start_response)
           ^^^^^^^^^^^^^^^^^^^^^^^^^^^^^^^^^^^^^^
  File "D:\Development\unknown_chat_bot v02\telegram_bot\.venv\Lib\site-packages\flask_socketio\__init__.py", line 43, in __call__
    return super(_SocketIOMiddleware, self).__call__(environ,
           ^^^^^^^^^^^^^^^^^^^^^^^^^^^^^^^^^^^^^^^^^^^^^^^^^^
  File "D:\Development\unknown_chat_bot v02\telegram_bot\.venv\Lib\site-packages\engineio\middleware.py", line 74, in __call__
    return self.wsgi_app(environ, start_response)
           ^^^^^^^^^^^^^^^^^^^^^^^^^^^^^^^^^^^^^^
  File "D:\Development\unknown_chat_bot v02\telegram_bot\.venv\Lib\site-packages\flask\app.py", line 2193, in wsgi_app
    response = self.handle_exception(e)
               ^^^^^^^^^^^^^^^^^^^^^^^^
  File "D:\Development\unknown_chat_bot v02\telegram_bot\.venv\Lib\site-packages\flask\app.py", line 1399, in handle_exception
    server_error = self.ensure_sync(handler)(server_error)
                   ^^^^^^^^^^^^^^^^^^^^^^^^^^^^^^^^^^^^^^^
  File "D:\Development\unknown_chat_bot v02\telegram_bot\error_handlers.py", line 50, in internal_error
    if request.path.startswith('/api/'):
       ^^^^^^^^^^^^^^^^^^^^^^^^^^^^^^^^^
NameError: name 'request' is not defined
2025-06-18 12:17:21,793 - werkzeug - INFO - [_internal.py:187] - 192.168.31.156 - - [18/Jun/2025 12:17:21] "GET /socket.io/?EIO=4&transport=websocket&sid=RzAZw7jLRrCIRbZWAAAA HTTP/1.1" 200 -
2025-06-18 12:17:21,811 - root - INFO - [app.py:441] - Request started: GET /admin/dashboard
2025-06-18 12:17:21,815 - root - INFO - [app.py:450] - Request completed: GET /admin/dashboard - Status: 200 - Duration: 0.00s
2025-06-18 12:17:21,816 - werkzeug - INFO - [_internal.py:187] - 192.168.31.156 - - [18/Jun/2025 12:17:21] "GET /admin/dashboard HTTP/1.1" 200 -
2025-06-18 12:17:22,055 - werkzeug - INFO - [_internal.py:187] - 192.168.31.156 - - [18/Jun/2025 12:17:22] "GET /socket.io/?EIO=4&transport=polling&t=PU1oj31 HTTP/1.1" 200 -
2025-06-18 12:17:22,120 - werkzeug - INFO - [_internal.py:187] - 192.168.31.156 - - [18/Jun/2025 12:17:22] "GET /socket.io/?EIO=4&transport=polling&t=PU1oj3r&sid=7KqAYoHloXPUjuUSAAAC HTTP/1.1" 200 -
2025-06-18 12:17:22,120 - werkzeug - INFO - [_internal.py:187] - 192.168.31.156 - - [18/Jun/2025 12:17:22] "POST /socket.io/?EIO=4&transport=polling&t=PU1oj3q&sid=7KqAYoHloXPUjuUSAAAC HTTP/1.1" 200 -
2025-06-18 12:17:22,176 - werkzeug - INFO - [_internal.py:187] - 192.168.31.156 - - [18/Jun/2025 12:17:22] "GET /socket.io/?EIO=4&transport=polling&t=PU1oj4I&sid=7KqAYoHloXPUjuUSAAAC HTTP/1.1" 200 -
2025-06-18 12:17:22,178 - root - INFO - [app.py:441] - Request started: GET /favicon.ico
2025-06-18 12:17:22,180 - app - ERROR - [app.py:1414] - Exception on /favicon.ico [GET]
Traceback (most recent call last):
  File "D:\Development\unknown_chat_bot v02\telegram_bot\.venv\Lib\site-packages\flask\app.py", line 1484, in full_dispatch_request
    rv = self.dispatch_request()
         ^^^^^^^^^^^^^^^^^^^^^^^
  File "D:\Development\unknown_chat_bot v02\telegram_bot\.venv\Lib\site-packages\flask\app.py", line 1458, in dispatch_request
    self.raise_routing_exception(req)
  File "D:\Development\unknown_chat_bot v02\telegram_bot\.venv\Lib\site-packages\flask\app.py", line 1440, in raise_routing_exception
    raise request.routing_exception  # type: ignore
    ^^^^^^^^^^^^^^^^^^^^^^^^^^^^^^^
  File "D:\Development\unknown_chat_bot v02\telegram_bot\.venv\Lib\site-packages\flask\ctx.py", line 353, in match_request
    result = self.url_adapter.match(return_rule=True)  # type: ignore
             ^^^^^^^^^^^^^^^^^^^^^^^^^^^^^^^^^^^^^^^^
  File "D:\Development\unknown_chat_bot v02\telegram_bot\.venv\Lib\site-packages\werkzeug\routing\map.py", line 655, in match
    raise NotFound() from None
werkzeug.exceptions.NotFound: 404 Not Found: The requested URL was not found on the server. If you entered the URL manually please check your spelling and try again.

During handling of the above exception, another exception occurred:

Traceback (most recent call last):
  File "D:\Development\unknown_chat_bot v02\telegram_bot\.venv\Lib\site-packages\flask\app.py", line 2190, in wsgi_app
    response = self.full_dispatch_request()
               ^^^^^^^^^^^^^^^^^^^^^^^^^^^^
  File "D:\Development\unknown_chat_bot v02\telegram_bot\.venv\Lib\site-packages\flask\app.py", line 1486, in full_dispatch_request
    rv = self.handle_user_exception(e)
         ^^^^^^^^^^^^^^^^^^^^^^^^^^^^^
  File "D:\Development\unknown_chat_bot v02\telegram_bot\.venv\Lib\site-packages\flask\app.py", line 1341, in handle_user_exception
    return self.handle_http_exception(e)
           ^^^^^^^^^^^^^^^^^^^^^^^^^^^^^
  File "D:\Development\unknown_chat_bot v02\telegram_bot\.venv\Lib\site-packages\flask\app.py", line 1281, in handle_http_exception
    return self.ensure_sync(handler)(e)
           ^^^^^^^^^^^^^^^^^^^^^^^^^^^^
  File "D:\Development\unknown_chat_bot v02\telegram_bot\error_handlers.py", line 37, in not_found_error
    if request.path.startswith('/api/'):
       ^^^^^^^
NameError: name 'request' is not defined
2025-06-18 12:17:22,188 - error_handlers - ERROR - [error_handlers.py:48] - Internal Server Error: 500 Internal Server Error: The server encountered an internal error and was unable to complete your request. Either the server is overloaded or there is an error in the application.
2025-06-18 12:17:22,195 - error_handlers - ERROR - [error_handlers.py:49] - Traceback (most recent call last):
  File "D:\Development\unknown_chat_bot v02\telegram_bot\.venv\Lib\site-packages\flask\app.py", line 1484, in full_dispatch_request
    rv = self.dispatch_request()
         ^^^^^^^^^^^^^^^^^^^^^^^
  File "D:\Development\unknown_chat_bot v02\telegram_bot\.venv\Lib\site-packages\flask\app.py", line 1458, in dispatch_request
    self.raise_routing_exception(req)
  File "D:\Development\unknown_chat_bot v02\telegram_bot\.venv\Lib\site-packages\flask\app.py", line 1440, in raise_routing_exception
    raise request.routing_exception  # type: ignore
    ^^^^^^^^^^^^^^^^^^^^^^^^^^^^^^^
  File "D:\Development\unknown_chat_bot v02\telegram_bot\.venv\Lib\site-packages\flask\ctx.py", line 353, in match_request
    result = self.url_adapter.match(return_rule=True)  # type: ignore
             ^^^^^^^^^^^^^^^^^^^^^^^^^^^^^^^^^^^^^^^^
  File "D:\Development\unknown_chat_bot v02\telegram_bot\.venv\Lib\site-packages\werkzeug\routing\map.py", line 655, in match
    raise NotFound() from None
werkzeug.exceptions.NotFound: 404 Not Found: The requested URL was not found on the server. If you entered the URL manually please check your spelling and try again.

During handling of the above exception, another exception occurred:

Traceback (most recent call last):
  File "D:\Development\unknown_chat_bot v02\telegram_bot\.venv\Lib\site-packages\flask\app.py", line 2190, in wsgi_app
    response = self.full_dispatch_request()
               ^^^^^^^^^^^^^^^^^^^^^^^^^^^^
  File "D:\Development\unknown_chat_bot v02\telegram_bot\.venv\Lib\site-packages\flask\app.py", line 1486, in full_dispatch_request
    rv = self.handle_user_exception(e)
         ^^^^^^^^^^^^^^^^^^^^^^^^^^^^^
  File "D:\Development\unknown_chat_bot v02\telegram_bot\.venv\Lib\site-packages\flask\app.py", line 1341, in handle_user_exception
    return self.handle_http_exception(e)
           ^^^^^^^^^^^^^^^^^^^^^^^^^^^^^
  File "D:\Development\unknown_chat_bot v02\telegram_bot\.venv\Lib\site-packages\flask\app.py", line 1281, in handle_http_exception
    return self.ensure_sync(handler)(e)
           ^^^^^^^^^^^^^^^^^^^^^^^^^^^^
  File "D:\Development\unknown_chat_bot v02\telegram_bot\error_handlers.py", line 37, in not_found_error
    if request.path.startswith('/api/'):
       ^^^^^^^
NameError: name 'request' is not defined

2025-06-18 12:17:22,197 - werkzeug - INFO - [_internal.py:187] - 192.168.31.156 - - [18/Jun/2025 12:17:22] "[35m[1mGET /favicon.ico HTTP/1.1[0m" 500 -
2025-06-18 12:17:22,211 - werkzeug - ERROR - [_internal.py:187] - Error on request:
Traceback (most recent call last):
  File "D:\Development\unknown_chat_bot v02\telegram_bot\.venv\Lib\site-packages\flask\app.py", line 1484, in full_dispatch_request
    rv = self.dispatch_request()
         ^^^^^^^^^^^^^^^^^^^^^^^
  File "D:\Development\unknown_chat_bot v02\telegram_bot\.venv\Lib\site-packages\flask\app.py", line 1458, in dispatch_request
    self.raise_routing_exception(req)
  File "D:\Development\unknown_chat_bot v02\telegram_bot\.venv\Lib\site-packages\flask\app.py", line 1440, in raise_routing_exception
    raise request.routing_exception  # type: ignore
  File "D:\Development\unknown_chat_bot v02\telegram_bot\.venv\Lib\site-packages\flask\ctx.py", line 353, in match_request
    result = self.url_adapter.match(return_rule=True)  # type: ignore
             ^^^^^^^^^^^^^^^^^^^^^^^^^^^^^^^^^^^^^^^^^^^^^^^^^^^^^^^^
  File "D:\Development\unknown_chat_bot v02\telegram_bot\.venv\Lib\site-packages\werkzeug\routing\map.py", line 655, in match
    raise NotFound() from None
werkzeug.exceptions.NotFound: 404 Not Found: The requested URL was not found on the server. If you entered the URL manually please check your spelling and try again.

During handling of the above exception, another exception occurred:

Traceback (most recent call last):
  File "D:\Development\unknown_chat_bot v02\telegram_bot\.venv\Lib\site-packages\flask\app.py", line 2190, in wsgi_app
    response = self.full_dispatch_request()
               ^^^^^^^^^^^^^^^^^^^^^^^^^^^^
  File "D:\Development\unknown_chat_bot v02\telegram_bot\.venv\Lib\site-packages\flask\app.py", line 1486, in full_dispatch_request
    rv = self.handle_user_exception(e)
         ^^^^^^^^^^^^^^^^^^^^^^^^^^^^^
  File "D:\Development\unknown_chat_bot v02\telegram_bot\.venv\Lib\site-packages\flask\app.py", line 1341, in handle_user_exception
    return self.handle_http_exception(e)
           ^^^^^^^^^^^^^^^^^^^^^^^^^^^^^
  File "D:\Development\unknown_chat_bot v02\telegram_bot\.venv\Lib\site-packages\flask\app.py", line 1281, in handle_http_exception
    return self.ensure_sync(handler)(e)
           ^^^^^^^^^^^^^^^^^^^^^^^^^^^^
  File "D:\Development\unknown_chat_bot v02\telegram_bot\error_handlers.py", line 37, in not_found_error
    if request.path.startswith('/api/'):
       ^^^^^^^^^^^^^^^^^^^^^^^^^^^^^^^^^
NameError: name 'request' is not defined

During handling of the above exception, another exception occurred:

Traceback (most recent call last):
  File "D:\Development\unknown_chat_bot v02\telegram_bot\.venv\Lib\site-packages\werkzeug\serving.py", line 364, in run_wsgi
    execute(self.server.app)
  File "D:\Development\unknown_chat_bot v02\telegram_bot\.venv\Lib\site-packages\werkzeug\serving.py", line 325, in execute
    application_iter = app(environ, start_response)
                       ^^^^^^^^^^^^^^^^^^^^^^^^^^^^
  File "D:\Development\unknown_chat_bot v02\telegram_bot\.venv\Lib\site-packages\flask\app.py", line 2213, in __call__
    return self.wsgi_app(environ, start_response)
           ^^^^^^^^^^^^^^^^^^^^^^^^^^^^^^^^^^^^^^
  File "D:\Development\unknown_chat_bot v02\telegram_bot\.venv\Lib\site-packages\flask_socketio\__init__.py", line 43, in __call__
    return super(_SocketIOMiddleware, self).__call__(environ,
           ^^^^^^^^^^^^^^^^^^^^^^^^^^^^^^^^^^^^^^^^^^^^^^^^^^
  File "D:\Development\unknown_chat_bot v02\telegram_bot\.venv\Lib\site-packages\engineio\middleware.py", line 74, in __call__
    return self.wsgi_app(environ, start_response)
           ^^^^^^^^^^^^^^^^^^^^^^^^^^^^^^^^^^^^^^
  File "D:\Development\unknown_chat_bot v02\telegram_bot\.venv\Lib\site-packages\flask\app.py", line 2193, in wsgi_app
    response = self.handle_exception(e)
               ^^^^^^^^^^^^^^^^^^^^^^^^
  File "D:\Development\unknown_chat_bot v02\telegram_bot\.venv\Lib\site-packages\flask\app.py", line 1399, in handle_exception
    server_error = self.ensure_sync(handler)(server_error)
                   ^^^^^^^^^^^^^^^^^^^^^^^^^^^^^^^^^^^^^^^
  File "D:\Development\unknown_chat_bot v02\telegram_bot\error_handlers.py", line 50, in internal_error
    if request.path.startswith('/api/'):
       ^^^^^^^^^^^^^^^^^^^^^^^^^^^^^^^^^
NameError: name 'request' is not defined
2025-06-18 12:17:22,730 - werkzeug - INFO - [_internal.py:187] - 192.168.31.156 - - [18/Jun/2025 12:17:22] "GET /socket.io/?EIO=4&transport=websocket&sid=7KqAYoHloXPUjuUSAAAC HTTP/1.1" 200 -
2025-06-18 12:17:22,761 - root - INFO - [app.py:441] - Request started: GET /admin/users
2025-06-18 12:17:22,793 - root - INFO - [app.py:450] - Request completed: GET /admin/users - Status: 200 - Duration: 0.03s
2025-06-18 12:17:22,794 - werkzeug - INFO - [_internal.py:187] - 192.168.31.156 - - [18/Jun/2025 12:17:22] "GET /admin/users HTTP/1.1" 200 -
2025-06-18 12:17:23,441 - root - INFO - [app.py:441] - Request started: GET /favicon.ico
2025-06-18 12:17:23,442 - app - ERROR - [app.py:1414] - Exception on /favicon.ico [GET]
Traceback (most recent call last):
  File "D:\Development\unknown_chat_bot v02\telegram_bot\.venv\Lib\site-packages\flask\app.py", line 1484, in full_dispatch_request
    rv = self.dispatch_request()
         ^^^^^^^^^^^^^^^^^^^^^^^
  File "D:\Development\unknown_chat_bot v02\telegram_bot\.venv\Lib\site-packages\flask\app.py", line 1458, in dispatch_request
    self.raise_routing_exception(req)
  File "D:\Development\unknown_chat_bot v02\telegram_bot\.venv\Lib\site-packages\flask\app.py", line 1440, in raise_routing_exception
    raise request.routing_exception  # type: ignore
    ^^^^^^^^^^^^^^^^^^^^^^^^^^^^^^^
  File "D:\Development\unknown_chat_bot v02\telegram_bot\.venv\Lib\site-packages\flask\ctx.py", line 353, in match_request
    result = self.url_adapter.match(return_rule=True)  # type: ignore
             ^^^^^^^^^^^^^^^^^^^^^^^^^^^^^^^^^^^^^^^^
  File "D:\Development\unknown_chat_bot v02\telegram_bot\.venv\Lib\site-packages\werkzeug\routing\map.py", line 655, in match
    raise NotFound() from None
werkzeug.exceptions.NotFound: 404 Not Found: The requested URL was not found on the server. If you entered the URL manually please check your spelling and try again.

During handling of the above exception, another exception occurred:

Traceback (most recent call last):
  File "D:\Development\unknown_chat_bot v02\telegram_bot\.venv\Lib\site-packages\flask\app.py", line 2190, in wsgi_app
    response = self.full_dispatch_request()
               ^^^^^^^^^^^^^^^^^^^^^^^^^^^^
  File "D:\Development\unknown_chat_bot v02\telegram_bot\.venv\Lib\site-packages\flask\app.py", line 1486, in full_dispatch_request
    rv = self.handle_user_exception(e)
         ^^^^^^^^^^^^^^^^^^^^^^^^^^^^^
  File "D:\Development\unknown_chat_bot v02\telegram_bot\.venv\Lib\site-packages\flask\app.py", line 1341, in handle_user_exception
    return self.handle_http_exception(e)
           ^^^^^^^^^^^^^^^^^^^^^^^^^^^^^
  File "D:\Development\unknown_chat_bot v02\telegram_bot\.venv\Lib\site-packages\flask\app.py", line 1281, in handle_http_exception
    return self.ensure_sync(handler)(e)
           ^^^^^^^^^^^^^^^^^^^^^^^^^^^^
  File "D:\Development\unknown_chat_bot v02\telegram_bot\error_handlers.py", line 37, in not_found_error
    if request.path.startswith('/api/'):
       ^^^^^^^
NameError: name 'request' is not defined
2025-06-18 12:17:23,449 - error_handlers - ERROR - [error_handlers.py:48] - Internal Server Error: 500 Internal Server Error: The server encountered an internal error and was unable to complete your request. Either the server is overloaded or there is an error in the application.
2025-06-18 12:17:23,456 - error_handlers - ERROR - [error_handlers.py:49] - Traceback (most recent call last):
  File "D:\Development\unknown_chat_bot v02\telegram_bot\.venv\Lib\site-packages\flask\app.py", line 1484, in full_dispatch_request
    rv = self.dispatch_request()
         ^^^^^^^^^^^^^^^^^^^^^^^
  File "D:\Development\unknown_chat_bot v02\telegram_bot\.venv\Lib\site-packages\flask\app.py", line 1458, in dispatch_request
    self.raise_routing_exception(req)
  File "D:\Development\unknown_chat_bot v02\telegram_bot\.venv\Lib\site-packages\flask\app.py", line 1440, in raise_routing_exception
    raise request.routing_exception  # type: ignore
    ^^^^^^^^^^^^^^^^^^^^^^^^^^^^^^^
  File "D:\Development\unknown_chat_bot v02\telegram_bot\.venv\Lib\site-packages\flask\ctx.py", line 353, in match_request
    result = self.url_adapter.match(return_rule=True)  # type: ignore
             ^^^^^^^^^^^^^^^^^^^^^^^^^^^^^^^^^^^^^^^^
  File "D:\Development\unknown_chat_bot v02\telegram_bot\.venv\Lib\site-packages\werkzeug\routing\map.py", line 655, in match
    raise NotFound() from None
werkzeug.exceptions.NotFound: 404 Not Found: The requested URL was not found on the server. If you entered the URL manually please check your spelling and try again.

During handling of the above exception, another exception occurred:

Traceback (most recent call last):
  File "D:\Development\unknown_chat_bot v02\telegram_bot\.venv\Lib\site-packages\flask\app.py", line 2190, in wsgi_app
    response = self.full_dispatch_request()
               ^^^^^^^^^^^^^^^^^^^^^^^^^^^^
  File "D:\Development\unknown_chat_bot v02\telegram_bot\.venv\Lib\site-packages\flask\app.py", line 1486, in full_dispatch_request
    rv = self.handle_user_exception(e)
         ^^^^^^^^^^^^^^^^^^^^^^^^^^^^^
  File "D:\Development\unknown_chat_bot v02\telegram_bot\.venv\Lib\site-packages\flask\app.py", line 1341, in handle_user_exception
    return self.handle_http_exception(e)
           ^^^^^^^^^^^^^^^^^^^^^^^^^^^^^
  File "D:\Development\unknown_chat_bot v02\telegram_bot\.venv\Lib\site-packages\flask\app.py", line 1281, in handle_http_exception
    return self.ensure_sync(handler)(e)
           ^^^^^^^^^^^^^^^^^^^^^^^^^^^^
  File "D:\Development\unknown_chat_bot v02\telegram_bot\error_handlers.py", line 37, in not_found_error
    if request.path.startswith('/api/'):
       ^^^^^^^
NameError: name 'request' is not defined

2025-06-18 12:17:23,458 - werkzeug - INFO - [_internal.py:187] - 192.168.31.156 - - [18/Jun/2025 12:17:23] "[35m[1mGET /favicon.ico HTTP/1.1[0m" 500 -
2025-06-18 12:17:23,478 - werkzeug - ERROR - [_internal.py:187] - Error on request:
Traceback (most recent call last):
  File "D:\Development\unknown_chat_bot v02\telegram_bot\.venv\Lib\site-packages\flask\app.py", line 1484, in full_dispatch_request
    rv = self.dispatch_request()
         ^^^^^^^^^^^^^^^^^^^^^^^
  File "D:\Development\unknown_chat_bot v02\telegram_bot\.venv\Lib\site-packages\flask\app.py", line 1458, in dispatch_request
    self.raise_routing_exception(req)
  File "D:\Development\unknown_chat_bot v02\telegram_bot\.venv\Lib\site-packages\flask\app.py", line 1440, in raise_routing_exception
    raise request.routing_exception  # type: ignore
  File "D:\Development\unknown_chat_bot v02\telegram_bot\.venv\Lib\site-packages\flask\ctx.py", line 353, in match_request
    result = self.url_adapter.match(return_rule=True)  # type: ignore
             ^^^^^^^^^^^^^^^^^^^^^^^^^^^^^^^^^^^^^^^^^^^^^^^^^^^^^^^^
  File "D:\Development\unknown_chat_bot v02\telegram_bot\.venv\Lib\site-packages\werkzeug\routing\map.py", line 655, in match
    raise NotFound() from None
werkzeug.exceptions.NotFound: 404 Not Found: The requested URL was not found on the server. If you entered the URL manually please check your spelling and try again.

During handling of the above exception, another exception occurred:

Traceback (most recent call last):
  File "D:\Development\unknown_chat_bot v02\telegram_bot\.venv\Lib\site-packages\flask\app.py", line 2190, in wsgi_app
    response = self.full_dispatch_request()
               ^^^^^^^^^^^^^^^^^^^^^^^^^^^^
  File "D:\Development\unknown_chat_bot v02\telegram_bot\.venv\Lib\site-packages\flask\app.py", line 1486, in full_dispatch_request
    rv = self.handle_user_exception(e)
         ^^^^^^^^^^^^^^^^^^^^^^^^^^^^^
  File "D:\Development\unknown_chat_bot v02\telegram_bot\.venv\Lib\site-packages\flask\app.py", line 1341, in handle_user_exception
    return self.handle_http_exception(e)
           ^^^^^^^^^^^^^^^^^^^^^^^^^^^^^
  File "D:\Development\unknown_chat_bot v02\telegram_bot\.venv\Lib\site-packages\flask\app.py", line 1281, in handle_http_exception
    return self.ensure_sync(handler)(e)
           ^^^^^^^^^^^^^^^^^^^^^^^^^^^^
  File "D:\Development\unknown_chat_bot v02\telegram_bot\error_handlers.py", line 37, in not_found_error
    if request.path.startswith('/api/'):
       ^^^^^^^^^^^^^^^^^^^^^^^^^^^^^^^^^
NameError: name 'request' is not defined

During handling of the above exception, another exception occurred:

Traceback (most recent call last):
  File "D:\Development\unknown_chat_bot v02\telegram_bot\.venv\Lib\site-packages\werkzeug\serving.py", line 364, in run_wsgi
    execute(self.server.app)
  File "D:\Development\unknown_chat_bot v02\telegram_bot\.venv\Lib\site-packages\werkzeug\serving.py", line 325, in execute
    application_iter = app(environ, start_response)
                       ^^^^^^^^^^^^^^^^^^^^^^^^^^^^
  File "D:\Development\unknown_chat_bot v02\telegram_bot\.venv\Lib\site-packages\flask\app.py", line 2213, in __call__
    return self.wsgi_app(environ, start_response)
           ^^^^^^^^^^^^^^^^^^^^^^^^^^^^^^^^^^^^^^
  File "D:\Development\unknown_chat_bot v02\telegram_bot\.venv\Lib\site-packages\flask_socketio\__init__.py", line 43, in __call__
    return super(_SocketIOMiddleware, self).__call__(environ,
           ^^^^^^^^^^^^^^^^^^^^^^^^^^^^^^^^^^^^^^^^^^^^^^^^^^
  File "D:\Development\unknown_chat_bot v02\telegram_bot\.venv\Lib\site-packages\engineio\middleware.py", line 74, in __call__
    return self.wsgi_app(environ, start_response)
           ^^^^^^^^^^^^^^^^^^^^^^^^^^^^^^^^^^^^^^
  File "D:\Development\unknown_chat_bot v02\telegram_bot\.venv\Lib\site-packages\flask\app.py", line 2193, in wsgi_app
    response = self.handle_exception(e)
               ^^^^^^^^^^^^^^^^^^^^^^^^
  File "D:\Development\unknown_chat_bot v02\telegram_bot\.venv\Lib\site-packages\flask\app.py", line 1399, in handle_exception
    server_error = self.ensure_sync(handler)(server_error)
                   ^^^^^^^^^^^^^^^^^^^^^^^^^^^^^^^^^^^^^^^
  File "D:\Development\unknown_chat_bot v02\telegram_bot\error_handlers.py", line 50, in internal_error
    if request.path.startswith('/api/'):
       ^^^^^^^^^^^^^^^^^^^^^^^^^^^^^^^^^
NameError: name 'request' is not defined
2025-06-18 12:17:36,309 - bot.handlers - INFO - [handlers.py:116] - Chat command - User 6261300717 data: {'username': 'jbiswas03', 'status': 'ready', 'joined_at': 1749957772.330016, 'partner': None, 'gender': 'M', 'interest': 'F', 'banned': False, 'last_active': 1750158066.5010402, 'wait_start': 1750153782.4772236, 'chat_start': 1750153792.4302967, 'connect_time': 1748201129.0450668}
2025-06-18 12:17:36,343 - bot.handlers - INFO - [handlers.py:102] - Finding partner for user 6261300717
2025-06-18 12:17:36,344 - bot.handlers - INFO - [handlers.py:103] - Available waiting users: {'6261300717': {'username': 'jbiswas03', 'status': 'waiting', 'joined_at': 1749957772.330016, 'partner': None, 'gender': 'M', 'interest': 'F', 'banned': False, 'last_active': 1750158066.5010402, 'wait_start': 1750229256.309824, 'chat_start': 1750153792.4302967, 'connect_time': 1748201129.0450668}}
2025-06-18 12:30:54,292 - bot.utils - WARNING - [utils.py:231] - Timeout on attempt 1 for sendMessage: HTTPSConnectionPool(host='api.telegram.org', port=443): Read timed out. (read timeout=20)
2025-06-18 12:31:01,123 - bot.handlers - INFO - [handlers.py:116] - Chat command - User 6261300717 data: {'username': 'jbiswas03', 'status': 'waiting', 'joined_at': 1749957772.330016, 'partner': None, 'gender': 'M', 'interest': 'F', 'banned': False, 'last_active': 1750158066.5010402, 'wait_start': 1750229256.309824, 'chat_start': 1750153792.4302967, 'connect_time': 1748201129.0450668}
2025-06-18 12:31:01,125 - bot.handlers - INFO - [handlers.py:102] - Finding partner for user 6261300717
2025-06-18 12:31:01,126 - bot.handlers - INFO - [handlers.py:103] - Available waiting users: {'6261300717': {'username': 'jbiswas03', 'status': 'waiting', 'joined_at': 1749957772.330016, 'partner': None, 'gender': 'M', 'interest': 'F', 'banned': False, 'last_active': 1750158066.5010402, 'wait_start': 1750229256.309824, 'chat_start': 1750153792.4302967, 'connect_time': 1748201129.0450668}}
